<?xml version="1.0" encoding="utf-8"?>
<!-- =================================================================================== -->
<!-- |    This document was autogenerated by xacro from ansrr_bot.xacro                | -->
<!-- |    EDITING THIS FILE BY HAND IS NOT RECOMMENDED                                 | -->
<!-- =================================================================================== -->
<robot name="ansrr_bot">
  <link name="base_link">
    <visual>
      <geometry>
        <box size="0.4572 0.4572 0.1524"/>
      </geometry>
      <material name="silver">
        <color rgba="0.75 0.75 0.75 1"/>
      </material>
    </visual>
    <collision>
      <geometry>
        <box size="0.4572 0.4572 0.1524"/>
      </geometry>
    </collision>
    <inertial>
      <mass value="1"/>
      <inertia ixx="0.01935" ixy="0" ixz="0" iyy="0.01935" iyz="0" izz="0.03483"/>
    </inertial>
  </link>
  <link name="left_front">
    <visual>
      <geometry>
        <cylinder length="0.0508" radius="0.0762"/>
      </geometry>
      <material name="black">
        <color rgba="0 0 0 1"/>
      </material>
    </visual>
    <collision>
      <geometry>
        <cylinder length="0.0508" radius="0.0762"/>
      </geometry>
    </collision>
    <inertial>
      <mass value="0.1"/>
      <inertia ixx="0.0005685" ixy="0" ixz="0" iyy="0.0005685" iyz="0" izz="0.0002903"/>
    </inertial>
  </link>
  <joint name="base_to_left_front" type="continuous">
    <axis xyz="0 0 1"/>
    <parent link="base_link"/>
    <child link="left_front"/>
    <origin rpy="1.5708 0 0" xyz="-0.1524 -0.25 -0.06096"/>
  </joint>
  <transmission name="left_front_joint_trans" type="SimpleTransmission">
    <actuator name="left_front_motor"/>
    <joint name="$base_to_{w_name}"/>
    <mechanicalReduction>1</mechanicalReduction>
    <motorTorqueConstant>1</motorTorqueConstant>
  </transmission>
  <link name="left_rear">
    <visual>
      <geometry>
        <cylinder length="0.0508" radius="0.0762"/>
      </geometry>
      <material name="black">
        <color rgba="0 0 0 1"/>
      </material>
    </visual>
    <collision>
      <geometry>
        <cylinder length="0.0508" radius="0.0762"/>
      </geometry>
    </collision>
    <inertial>
      <mass value="0.1"/>
      <inertia ixx="0.0005685" ixy="0" ixz="0" iyy="0.0005685" iyz="0" izz="0.0002903"/>
    </inertial>
  </link>
  <joint name="base_to_left_rear" type="continuous">
    <axis xyz="0 0 1"/>
    <parent link="base_link"/>
    <child link="left_rear"/>
    <origin rpy="1.5708 0 0" xyz="0.1524 -0.25 -0.06096"/>
  </joint>
  <transmission name="left_rear_joint_trans" type="SimpleTransmission">
    <actuator name="left_rear_motor"/>
    <joint name="$base_to_{w_name}"/>
    <mechanicalReduction>1</mechanicalReduction>
    <motorTorqueConstant>1</motorTorqueConstant>
  </transmission>
  <link name="right_front">
    <visual>
      <geometry>
        <cylinder length="0.0508" radius="0.0762"/>
      </geometry>
      <material name="black">
        <color rgba="0 0 0 1"/>
      </material>
    </visual>
    <collision>
      <geometry>
        <cylinder length="0.0508" radius="0.0762"/>
      </geometry>
    </collision>
    <inertial>
      <mass value="0.1"/>
      <inertia ixx="0.0005685" ixy="0" ixz="0" iyy="0.0005685" iyz="0" izz="0.0002903"/>
    </inertial>
  </link>
  <joint name="base_to_right_front" type="continuous">
    <axis xyz="0 0 1"/>
    <parent link="base_link"/>
    <child link="right_front"/>
    <origin rpy="1.5708 0 0" xyz="-0.1524 0.25 -0.06096"/>
  </joint>
  <transmission name="right_front_joint_trans" type="SimpleTransmission">
    <actuator name="right_front_motor"/>
    <joint name="$base_to_{w_name}"/>
    <mechanicalReduction>1</mechanicalReduction>
    <motorTorqueConstant>1</motorTorqueConstant>
  </transmission>
  <link name="right_rear">
    <visual>
      <geometry>
        <cylinder length="0.0508" radius="0.0762"/>
      </geometry>
      <material name="black">
        <color rgba="0 0 0 1"/>
      </material>
    </visual>
    <collision>
      <geometry>
        <cylinder length="0.0508" radius="0.0762"/>
      </geometry>
    </collision>
    <inertial>
      <mass value="0.1"/>
      <inertia ixx="0.0005685" ixy="0" ixz="0" iyy="0.0005685" iyz="0" izz="0.0002903"/>
    </inertial>
  </link>
  <joint name="base_to_right_rear" type="continuous">
    <axis xyz="0 0 1"/>
    <parent link="base_link"/>
    <child link="right_rear"/>
    <origin rpy="1.5708 0 0" xyz="0.1524 0.25 -0.06096"/>
  </joint>
  <transmission name="right_rear_joint_trans" type="SimpleTransmission">
    <actuator name="right_rear_motor"/>
    <joint name="$base_to_{w_name}"/>
    <mechanicalReduction>1</mechanicalReduction>
    <motorTorqueConstant>1</motorTorqueConstant>
  </transmission>
  <link name="lidar">
    <visual>
      <geometry>
        <box size="0.05 0.05 0.05"/>
      </geometry>
    </visual>
    <collision>
      <geometry>
        <box size="0.05 0.05 0.05"/>
      </geometry>
    </collision>
    <inertial>
      <mass value="0.05"/>
      <inertia ixx="0.01" ixy="0" ixz="0" iyy="0.01" iyz="0" izz="0.01"/>
    </inertial>
  </link>
  <joint name="base_to_lidar" type="fixed">
    <axis xyz="0 0 1"/>
    <parent link="base_link"/>
    <child link="lidar"/>
    <origin rpy="0 0 3.14" xyz="-.2286 0 0.1"/>
  </joint>
  <gazebo>
    <plugin filename="libgazebo_ros_diff_drive.so" name="differential_drive_controller">
      <leftJoint>base_to_left_rear</leftJoint>
      <rightJoint>base_to_right_rear</rightJoint>
      <robotBaseFrame>base_link</robotBaseFrame>
      <wheelSeparation>0.4064</wheelSeparation>
      <wheelDiameter>0.1524</wheelDiameter>
      <publishWheelJointState>true</publishWheelJointState>
    </plugin>
    <plugin filename="libgazebo_ros_diff_drive.so" name="differential_drive_controller">
      <leftJoint>base_to_left_front</leftJoint>
      <rightJoint>base_to_right_front</rightJoint>
      <robotBaseFrame>base_link</robotBaseFrame>
      <wheelSeparation>0.4064</wheelSeparation>
      <wheelDiameter>0.1524</wheelDiameter>
      <publishWheelJointState>true</publishWheelJointState>
    </plugin>
  </gazebo>
  <gazebo reference="lidar">
    <sensor name="lds_lfcd_sensor" type="ray">
      <pose>0 0 0 0 0 0</pose>
      <visualize>0</visualize>
      <update_rate>40</update_rate>
      <ray>
        <scan>
          <horizontal>
            <samples>360</samples>
            <resolution>1</resolution>
            <min_angle>0</min_angle>
            <max_angle>6.28</max_angle>
          </horizontal>
        </scan>
        <range>
          <min>0.1</min>
          <max>11</max>
          <resolution>0.01</resolution>
        </range>
      </ray>
      <plugin filename="libgazebo_ros_laser.so" name="gazebo_ros_lds_lfcd_controller  ">
        <topicName>/scan</topicName>
        <frameName>lidar</frameName>
      </plugin>
    </sensor>
  </gazebo>
  <link name="us_link_1">
    <visual>
      <geometry>
        <box size="0.01 0.05 0.01"/>
      </geometry>
    </visual>
    <collision>
      <geometry>
        <box size="0.05 0.05 0.05"/>
      </geometry>
    </collision>
    <inertial>
      <mass value="0.05"/>
      <inertia ixx="0.01" ixy="0" ixz="0" iyy="0.01" iyz="0" izz="0.01"/>
    </inertial>
  </link>
  <joint name="base_to_us_link_1" type="fixed">
    <axis xyz="0 0 1"/>
    <parent link="base_link"/>
    <child link="us_link_1"/>
    <origin rpy="0 .5 -2.356" xyz="-.21 -0.2 0.15"/>
  </joint>
  <gazebo reference="us_link_1">
    <sensor name="us1" type="ray">
      <pose>0 0 0 0 0 0</pose>
      <visualize>1</visualize>
      <update_rate>40</update_rate>
      <ray>
        <scan>
          <horizontal>
            <samples>10</samples>
            <resolution>5</resolution>
            <min_angle>-0.1484</min_angle>
            <max_angle>0.1484</max_angle>
          </horizontal>
          <vertical>
            <samples>10</samples>
            <resolution>5</resolution>
            <min_angle>-0.2967</min_angle>
            <max_angle>0</max_angle>
          </vertical>
        </scan>
        <range>
          <min>0.1</min>
          <max>0.7</max>
          <resolution>0.01</resolution>
        </range>
      </ray>
      <plugin filename="libgazebo_ros_range.so" name="gazebo_ros_us1">
        <gaussianNoise>0.005</gaussianNoise>
        <alwaysOn>true</alwaysOn>
        <updateRate>50</updateRate>
        <topicName>ultrasound_1</topicName>
        <frameName>us_link_1</frameName>
        <radiation>ULTRASOUND</radiation>
        <fov>0.2967</fov>
      </plugin>
    </sensor>
  </gazebo>
  <link name="us_link_2">
    <visual>
      <geometry>
        <box size="0.01 0.05 0.01"/>
      </geometry>
    </visual>
    <collision>
      <geometry>
        <box size="0.05 0.05 0.05"/>
      </geometry>
    </collision>
    <inertial>
      <mass value="0.05"/>
      <inertia ixx="0.01" ixy="0" ixz="0" iyy="0.01" iyz="0" izz="0.01"/>
    </inertial>
  </link>
  <joint name="base_to_us_link_2" type="fixed">
    <axis xyz="0 0 1"/>
    <parent link="base_link"/>
    <child link="us_link_2"/>
    <origin rpy="0 .5 3.14" xyz="-.2286 -0.1 0.15"/>
  </joint>
  <gazebo reference="us_link_2">
    <sensor name="us2" type="ray">
      <pose>0 0 0 0 0 0</pose>
      <visualize>1</visualize>
      <update_rate>40</update_rate>
      <ray>
        <scan>
          <horizontal>
            <samples>10</samples>
            <resolution>5</resolution>
            <min_angle>-0.1484</min_angle>
            <max_angle>0.1484</max_angle>
          </horizontal>
          <vertical>
            <samples>10</samples>
            <resolution>5</resolution>
            <min_angle>-0.2967</min_angle>
            <max_angle>0</max_angle>
          </vertical>
        </scan>
        <range>
          <min>0.1</min>
          <max>0.7</max>
          <resolution>0.01</resolution>
        </range>
      </ray>
      <plugin filename="libgazebo_ros_range.so" name="gazebo_ros_us2">
        <gaussianNoise>0.005</gaussianNoise>
        <alwaysOn>true</alwaysOn>
        <updateRate>50</updateRate>
        <topicName>ultrasound_2</topicName>
        <frameName>us_link_2</frameName>
        <radiation>ULTRASOUND</radiation>
        <fov>0.2967</fov>
      </plugin>
    </sensor>
  </gazebo>
  <link name="us_link_3">
    <visual>
      <geometry>
        <box size="0.01 0.05 0.01"/>
      </geometry>
    </visual>
    <collision>
      <geometry>
        <box size="0.05 0.05 0.05"/>
      </geometry>
    </collision>
    <inertial>
      <mass value="0.05"/>
      <inertia ixx="0.01" ixy="0" ixz="0" iyy="0.01" iyz="0" izz="0.01"/>
    </inertial>
  </link>
  <joint name="base_to_us_link_3" type="fixed">
    <axis xyz="0 0 1"/>
    <parent link="base_link"/>
    <child link="us_link_3"/>
    <origin rpy="0 0.5 3.14" xyz="-.2286 0 0.15"/>
  </joint>
  <gazebo reference="us_link_3">
    <sensor name="us3" type="ray">
      <pose>0 0 0 0 0 0</pose>
      <visualize>1</visualize>
      <update_rate>40</update_rate>
      <ray>
        <scan>
          <horizontal>
            <samples>10</samples>
            <resolution>5</resolution>
            <min_angle>-0.1484</min_angle>
            <max_angle>0.1484</max_angle>
          </horizontal>
          <vertical>
            <samples>10</samples>
            <resolution>5</resolution>
            <min_angle>-0.2967</min_angle>
            <max_angle>0</max_angle>
          </vertical>
        </scan>
        <range>
          <min>0.1</min>
          <max>0.7</max>
          <resolution>0.01</resolution>
        </range>
      </ray>
      <plugin filename="libgazebo_ros_range.so" name="gazebo_ros_us3">
        <gaussianNoise>0.005</gaussianNoise>
        <alwaysOn>true</alwaysOn>
        <updateRate>50</updateRate>
        <topicName>ultrasound_3</topicName>
        <frameName>us_link_3</frameName>
        <radiation>ULTRASOUND</radiation>
        <fov>0.2967</fov>
      </plugin>
    </sensor>
  </gazebo>
  <link name="us_link_4">
    <visual>
      <geometry>
        <box size="0.01 0.05 0.01"/>
      </geometry>
    </visual>
    <collision>
      <geometry>
        <box size="0.05 0.05 0.05"/>
      </geometry>
    </collision>
    <inertial>
      <mass value="0.05"/>
      <inertia ixx="0.01" ixy="0" ixz="0" iyy="0.01" iyz="0" izz="0.01"/>
    </inertial>
  </link>
  <joint name="base_to_us_link_4" type="fixed">
    <axis xyz="0 0 1"/>
    <parent link="base_link"/>
    <child link="us_link_4"/>
    <origin rpy="0 0.5 3.14" xyz="-.2286 0.1 0.15"/>
  </joint>
  <gazebo reference="us_link_4">
    <sensor name="us4" type="ray">
      <pose>0 0 0 0 0 0</pose>
      <visualize>1</visualize>
      <update_rate>40</update_rate>
      <ray>
        <scan>
          <horizontal>
            <samples>10</samples>
            <resolution>5</resolution>
            <min_angle>-0.1484</min_angle>
            <max_angle>0.1484</max_angle>
          </horizontal>
          <vertical>
            <samples>10</samples>
            <resolution>5</resolution>
            <min_angle>-0.2967</min_angle>
            <max_angle>0</max_angle>
          </vertical>
        </scan>
        <range>
          <min>0.1</min>
          <max>0.7</max>
          <resolution>0.01</resolution>
        </range>
      </ray>
      <plugin filename="libgazebo_ros_range.so" name="gazebo_ros_us4">
        <gaussianNoise>0.005</gaussianNoise>
        <alwaysOn>true</alwaysOn>
        <updateRate>50</updateRate>
        <topicName>ultrasound_4</topicName>
        <frameName>us_link_4</frameName>
        <radiation>ULTRASOUND</radiation>
        <fov>0.2967</fov>
      </plugin>
    </sensor>
  </gazebo>
  <link name="us_link_5">
    <visual>
      <geometry>
        <box size="0.01 0.05 0.01"/>
      </geometry>
    </visual>
    <collision>
      <geometry>
        <box size="0.05 0.05 0.05"/>
      </geometry>
    </collision>
    <inertial>
      <mass value="0.05"/>
      <inertia ixx="0.01" ixy="0" ixz="0" iyy="0.01" iyz="0" izz="0.01"/>
    </inertial>
  </link>
  <joint name="base_to_us_link_5" type="fixed">
    <axis xyz="0 0 1"/>
    <parent link="base_link"/>
    <child link="us_link_5"/>
    <origin rpy="0 0.5 2.356" xyz="-.21 0.2 0.15"/>
  </joint>
  <gazebo reference="us_link_5">
    <sensor name="us5" type="ray">
      <pose>0 0 0 0 0 0</pose>
      <visualize>1</visualize>
      <update_rate>40</update_rate>
      <ray>
        <scan>
          <horizontal>
            <samples>10</samples>
            <resolution>5</resolution>
            <min_angle>-0.1484</min_angle>
            <max_angle>0.1484</max_angle>
          </horizontal>
          <vertical>
            <samples>10</samples>
            <resolution>5</resolution>
            <min_angle>-0.2967</min_angle>
            <max_angle>0</max_angle>
          </vertical>
        </scan>
        <range>
          <min>0.1</min>
          <max>0.7</max>
          <resolution>0.01</resolution>
        </range>
      </ray>
      <plugin filename="libgazebo_ros_range.so" name="gazebo_ros_us5">
        <gaussianNoise>0.005</gaussianNoise>
        <alwaysOn>true</alwaysOn>
        <updateRate>50</updateRate>
        <topicName>ultrasound_5</topicName>
        <frameName>us_link_5</frameName>
        <radiation>ULTRASOUND</radiation>
        <fov>0.2967</fov>
      </plugin>
    </sensor>
  </gazebo>
</robot>

