<?xml version="1.0" encoding="UTF-8"?>
<robot xmlns:xacro="http://www.ros.org/wiki/xacro">
<xacro:property name="box_x" value="0.4572"/>
<xacro:property name="box_y" value="0.4572"/>
<xacro:property name="box_z" value="0.1524"/>

<xacro:property name="box_mass" value= "1"/>
<xacro:property name="box_ixx" value= "0.01935"/>
<xacro:property name="box_iyy" value= "0.01935"/>
<xacro:property name="box_izz" value= "0.03483"/>

<xacro:property name="length" value="0.0508"/>
<xacro:property name="wheel_radius" value="0.0762"/>

<xacro:property name="wheel_mass" value= "0.1"/>
<xacro:property name="wheel_ixx" value= "5.685e-4"/>
<xacro:property name="wheel_iyy" value= "5.685e-4"/>
<xacro:property name="wheel_izz" value= "2.903e-4"/>

<xacro:property name="front_x" value="0.1524"/>
<xacro:property name="rear_x" value="-0.1524"/>
<xacro:property name="wheel_y" value="0.25"/>
<xacro:property name="wheel_z" value="-0.06096"/>

<xacro:macro name="ultrasound_macro" params="ref sens_name plugin_name topic_name frame_name">
  <gazebo reference="${ref}">
    <sensor name="${sens_name}" type="ray">
      <pose>0 0 0 0 0 0</pose>
      <visualize>1</visualize>
      <update_rate>40</update_rate>
      <ray>
        <scan>
          <horizontal>
            <samples>10</samples>
            <resolution>5</resolution>
            <min_angle>-0.1484</min_angle>
            <max_angle>0.1484</max_angle>
          </horizontal>
          <vertical>
            <samples>10</samples>
            <resolution>5</resolution>
            <min_angle>-0.2967</min_angle>
            <max_angle>0</max_angle>
          </vertical>
        </scan>
        <range>
          <min>0.1</min>
          <max>0.7</max>
          <resolution>0.01</resolution>
        </range>
      </ray>
      <plugin filename="libgazebo_ros_range.so" name="${plugin_name}">
        <gaussianNoise>0.005</gaussianNoise>
        <alwaysOn>true</alwaysOn>
        <updateRate>50</updateRate>
        <topicName>${topic_name}</topicName>
        <frameName>${frame_name}</frameName>
        <radiation>ULTRASOUND</radiation>
        <fov>0.2967</fov>
      </plugin>
    </sensor>
  </gazebo>
</xacro:macro>

<xacro:macro name="geo_box">
  <geometry>
    <box size="${box_x} ${box_y} ${box_z}"/>
  </geometry>
</xacro:macro>

<xacro:macro name="inertia_macro" params="mass ixx iyy izz">
  <inertial>
    <mass value="${mass}"/>
    <inertia ixx="${ixx}" iyy="${iyy}" izz="${izz}" ixy="0" ixz="0" iyz="0"/>
  </inertial>
</xacro:macro>

<xacro:macro name="us_link" params="link_name *orig">
  <link name="${link_name}">
    <visual>
      <geometry>
        <box size="0.01 0.05 0.01"/>
      </geometry>
    </visual>
    <collision>
      <geometry>
        <box size="0.05 0.05 0.05"/>
      </geometry>
    </collision>
    <xacro:inertia_macro mass="0.05" ixx="0.01" iyy="0.01" izz="0.01"/>
  </link>
  <joint name="base_to_${link_name}" type="fixed">
    <axis xyz="0 0 1"/>
    <parent link="base_link"/>
    <child link="${link_name}"/>
    <xacro:insert_block name="orig"/>
  </joint>
</xacro:macro>

<xacro:macro name="wheel" params="w_name x y z">
  <link name="${w_name}">
    <visual>
      <geometry>
        <cylinder length="${length}" radius="${wheel_radius}"/>
      </geometry>
      <material name="black">
        <color rgba="0 0 0 1"/>
      </material>
    </visual>
    <collision>
      <geometry>
        <cylinder length="${length}" radius="${wheel_radius}"/>
      </geometry>
    </collision>
    <xacro:inertia_macro mass="${wheel_mass}" ixx="${wheel_ixx}" iyy="${wheel_iyy}" izz="${wheel_izz}"/>
  </link>
  <joint name="base_to_${w_name}" type="continuous">
    <axis xyz="0 0 1"/>
    <parent link="base_link"/>
    <child link="${w_name}"/>
    <origin rpy="1.5708 0 3.14" xyz="${x} ${y} ${z}"/>
  </joint>
  <transmission name="${w_name}_joint_trans" type="SimpleTransmission">
      <actuator name="${w_name}_motor"/>
      <joint name="$base_to_{w_name}"/>
      <mechanicalReduction>1</mechanicalReduction>
      <motorTorqueConstant>1</motorTorqueConstant>
  </transmission>

</xacro:macro>
</robot>
